<mujoco model="armature">
  <option integrator="RK4" timestep="0.01" />
  <default>
    <joint armature="0.01" damping="1" limited="true" />
    <geom friction="1 0.1 0.1" density="5" />
  </default>
  <asset>
    <texture builtin="flat" name="texplane" width="1" height="1" rgb1="0.8 0.6 0.4" />
    <material name="matplane" texture="texplane" />
  </asset>
  <worldbody>
    <geom name="floor" type="plane" size="10 10 0.1" material="matplane" />
    <light name="top" pos="0 0 2" mode="trackcom"/>

    <body name="Hips" pos="0.001 0.792 1.000">
      <geom type="capsule" fromto="0 0 0 -0.000 0.063 -0.054" size="0.05" />
      <freejoint />

      <body name="Spine" pos="0.000 0.000 0.000">
        <geom type="capsule" fromto="0 0 0 0.000 -0.253 -0.000" size="0.05" />
        <joint name="Spine_x" type="hinge" axis="1 0 0" pos="0 0 0" range="-90 90"/>
        <joint name="Spine_y" type="hinge" axis="0 1 0" pos="0 0 0" range="-90 90"/>
        <joint name="Spine_z" type="hinge" axis="0 0 1" pos="0 0 0" range="-90 90"/>

        <body name="Spine1" pos="0.000 -0.362 -0.000">
          <geom type="capsule" fromto="0 0 0 0.000 -0.276 -0.036" size="0.05" />
          <joint name="Spine1_x" type="hinge" axis="1 0 0" pos="0 0 0" range="-90 90"/>
          <joint name="Spine1_y" type="hinge" axis="0 1 0" pos="0 0 0" range="-90 90"/>
          <joint name="Spine1_z" type="hinge" axis="0 0 1" pos="0 0 0" range="-90 90"/>

          <body name="Neck" pos="0.000 -0.429 -0.011">
            <geom type="capsule" fromto="0 0 0 0.000 -0.187 -0.000" size="0.05" />
            <joint name="Neck_x" type="hinge" axis="1 0 0" pos="0 0 0" range="-90 90"/>
            <joint name="Neck_y" type="hinge" axis="0 1 0" pos="0 0 0" range="-90 90"/>
            <joint name="Neck_z" type="hinge" axis="0 0 1" pos="0 0 0" range="-90 90"/>

            <body name="Head" pos="0.000 -0.267 -0.001">
              <geom type="capsule" fromto="0 0 0 0.000 -0.227 -0.000" size="0.05" />
              <joint name="Head_x" type="hinge" axis="1 0 0" pos="0 0 0" range="-90 90"/>
              <joint name="Head_y" type="hinge" axis="0 1 0" pos="0 0 0" range="-90 90"/>
              <joint name="Head_z" type="hinge" axis="0 0 1" pos="0 0 0" range="-90 90"/>
            </body>
          </body>

          <body name="LeftShoulder" pos="0.082 -0.377 -0.071">
            <geom type="capsule" fromto="0 0 0 -0.000 0.000 -0.107" size="0.05" />
            <joint name="LeftShoulder_x" type="hinge" axis="1 0 0" pos="0 0 0" range="-90 90"/>
            <joint name="LeftShoulder_y" type="hinge" axis="0 1 0" pos="0 0 0" range="-90 90"/>
            <joint name="LeftShoulder_z" type="hinge" axis="0 0 1" pos="0 0 0" range="-90 90"/>

            <body name="LeftArm" pos="-0.000 0.000 -0.152">
              <geom type="capsule" fromto="0 0 0 -0.000 0.000 -0.203" size="0.05" />
              <joint name="LeftArm_x" type="hinge" axis="1 0 0" pos="0 0 0" range="-90 90"/>
              <joint name="LeftArm_y" type="hinge" axis="0 1 0" pos="0 0 0" range="-90 90"/>
              <joint name="LeftArm_z" type="hinge" axis="0 0 1" pos="0 0 0" range="-90 90"/>

              <body name="LeftForeArm" pos="-0.000 0.000 -0.290">
                <geom type="capsule" fromto="0 0 0 -0.000 0.000 -0.237" size="0.05" />
                <joint name="LeftForeArm_x" type="hinge" axis="1 0 0" pos="0 0 0" range="-90 90"/>
                <joint name="LeftForeArm_y" type="hinge" axis="0 1 0" pos="0 0 0" range="-90 90"/>
                <joint name="LeftForeArm_z" type="hinge" axis="0 0 1" pos="0 0 0" range="-90 90"/>

                <body name="LeftHand" pos="-0.000 0.000 -0.339">
                  <geom type="capsule" fromto="0 0 0 -0.000 0.000 -0.096" size="0.05" />
                  <joint name="LeftHand_x" type="hinge" axis="1 0 0" pos="0 0 0" range="-90 90"/>
                  <joint name="LeftHand_y" type="hinge" axis="0 1 0" pos="0 0 0" range="-90 90"/>
                  <joint name="LeftHand_z" type="hinge" axis="0 0 1" pos="0 0 0" range="-90 90"/>

                  <body name="LeftFinger" pos="-0.000 0.000 -0.137">
                    <geom type="capsule" fromto="0 0 0 -0.000 -0.067 -0.000" size="0.05" />
                    <joint name="LeftFinger_x" type="hinge" axis="1 0 0" pos="0 0 0" range="-90 90"/>
                    <joint name="LeftFinger_y" type="hinge" axis="0 1 0" pos="0 0 0" range="-90 90"/>
                    <joint name="LeftFinger_z" type="hinge" axis="0 0 1" pos="0 0 0" range="-90 90"/>
                  </body>
                </body>
              </body>
            </body>
          </body>

          <body name="RightShoulder" pos="-0.082 -0.377 -0.071">
            <geom type="capsule" fromto="0 0 0 0.002 0.000 -0.107" size="0.05" />
            <joint name="RightShoulder_x" type="hinge" axis="1 0 0" pos="0 0 0" range="-90 90"/>
            <joint name="RightShoulder_y" type="hinge" axis="0 1 0" pos="0 0 0" range="-90 90"/>
            <joint name="RightShoulder_z" type="hinge" axis="0 0 1" pos="0 0 0" range="-90 90"/>

            <body name="RightArm" pos="0.003 0.000 -0.152">
              <geom type="capsule" fromto="0 0 0 -0.000 0.000 -0.203" size="0.05" />
              <joint name="RightArm_x" type="hinge" axis="1 0 0" pos="0 0 0" range="-90 90"/>
              <joint name="RightArm_y" type="hinge" axis="0 1 0" pos="0 0 0" range="-90 90"/>
              <joint name="RightArm_z" type="hinge" axis="0 0 1" pos="0 0 0" range="-90 90"/>

              <body name="RightForeArm" pos="-0.000 0.000 -0.290">
                <geom type="capsule" fromto="0 0 0 -0.000 0.000 -0.237" size="0.05" />
                <joint name="RightForeArm_x" type="hinge" axis="1 0 0" pos="0 0 0" range="-90 90"/>
                <joint name="RightForeArm_y" type="hinge" axis="0 1 0" pos="0 0 0" range="-90 90"/>
                <joint name="RightForeArm_z" type="hinge" axis="0 0 1" pos="0 0 0" range="-90 90"/>

                <body name="RightHand" pos="-0.000 0.000 -0.339">
                  <geom type="capsule" fromto="0 0 0 -0.000 0.000 -0.096" size="0.05" />
                  <joint name="RightHand_x" type="hinge" axis="1 0 0" pos="0 0 0" range="-90 90"/>
                  <joint name="RightHand_y" type="hinge" axis="0 1 0" pos="0 0 0" range="-90 90"/>
                  <joint name="RightHand_z" type="hinge" axis="0 0 1" pos="0 0 0" range="-90 90"/>

                  <body name="RightFinger" pos="-0.000 0.000 -0.137">
                    <geom type="capsule" fromto="0 0 0 0.000 -0.067 -0.000" size="0.05" />
                    <joint name="RightFinger_x" type="hinge" axis="1 0 0" pos="0 0 0" range="-90 90"/>
                    <joint name="RightFinger_y" type="hinge" axis="0 1 0" pos="0 0 0" range="-90 90"/>
                    <joint name="RightFinger_z" type="hinge" axis="0 0 1" pos="0 0 0" range="-90 90"/>
                  </body>
                </body>
              </body>
            </body>
          </body>
        </body>
      </body>

      <body name="LeftUpLeg" pos="0.091 0.114 -0.146">
        <geom type="capsule" fromto="0 0 0 -0.000 0.000 -0.213" size="0.05" />
        <joint name="LeftUpLeg_x" type="hinge" axis="1 0 0" pos="0 0 0" range="-90 90"/>
        <joint name="LeftUpLeg_y" type="hinge" axis="0 1 0" pos="0 0 0" range="-90 90"/>
        <joint name="LeftUpLeg_z" type="hinge" axis="0 0 1" pos="0 0 0" range="-90 90"/>

        <body name="LeftLeg" pos="-0.000 0.000 -0.305">
          <geom type="capsule" fromto="0 0 0 -0.000 0.000 -0.240" size="0.05" />
          <joint name="LeftLeg_x" type="hinge" axis="1 0 0" pos="0 0 0" range="-90 90"/>
          <joint name="LeftLeg_y" type="hinge" axis="0 1 0" pos="0 0 0" range="-90 90"/>
          <joint name="LeftLeg_z" type="hinge" axis="0 0 1" pos="0 0 0" range="-90 90"/>

          <body name="LeftFoot" pos="-0.000 0.000 -0.343">
            <geom type="capsule" fromto="0 0 0 -0.000 0.000 -0.144" size="0.05" />
            <joint name="LeftFoot_x" type="hinge" axis="1 0 0" pos="0 0 0" range="-90 90"/>
            <joint name="LeftFoot_y" type="hinge" axis="0 1 0" pos="0 0 0" range="-90 90"/>
            <joint name="LeftFoot_z" type="hinge" axis="0 0 1" pos="0 0 0" range="-90 90"/>

            <body name="LeftToe" pos="-0.000 0.000 -0.206">
              <geom type="capsule" fromto="0 0 0 0.000 -0.133 -0.000" size="0.05" />
              <joint name="LeftToe_x" type="hinge" axis="1 0 0" pos="0 0 0" range="-90 90"/>
              <joint name="LeftToe_y" type="hinge" axis="0 1 0" pos="0 0 0" range="-90 90"/>
              <joint name="LeftToe_z" type="hinge" axis="0 0 1" pos="0 0 0" range="-90 90"/>
            </body>
          </body>
        </body>
      </body>

      <body name="RightUpLeg" pos="-0.091 0.114 -0.146">
        <geom type="capsule" fromto="0 0 0 -0.000 0.000 -0.213" size="0.05" />
        <joint name="RightUpLeg_x" type="hinge" axis="1 0 0" pos="0 0 0" range="-90 90"/>
        <joint name="RightUpLeg_y" type="hinge" axis="0 1 0" pos="0 0 0" range="-90 90"/>
        <joint name="RightUpLeg_z" type="hinge" axis="0 0 1" pos="0 0 0" range="-90 90"/>

        <body name="RightLeg" pos="-0.000 0.000 -0.305">
          <geom type="capsule" fromto="0 0 0 -0.000 0.000 -0.240" size="0.05" />
          <joint name="RightLeg_x" type="hinge" axis="1 0 0" pos="0 0 0" range="-90 90"/>
          <joint name="RightLeg_y" type="hinge" axis="0 1 0" pos="0 0 0" range="-90 90"/>
          <joint name="RightLeg_z" type="hinge" axis="0 0 1" pos="0 0 0" range="-90 90"/>

          <body name="RightFoot" pos="-0.000 0.000 -0.343">
            <geom type="capsule" fromto="0 0 0 -0.000 0.000 -0.144" size="0.05" />
            <joint name="RightFoot_x" type="hinge" axis="1 0 0" pos="0 0 0" range="-90 90"/>
            <joint name="RightFoot_y" type="hinge" axis="0 1 0" pos="0 0 0" range="-90 90"/>
            <joint name="RightFoot_z" type="hinge" axis="0 0 1" pos="0 0 0" range="-90 90"/>

            <body name="RightToe" pos="-0.000 0.000 -0.206">
              <geom type="capsule" fromto="0 0 0 0.000 -0.133 -0.000" size="0.05" />
              <joint name="RightToe_x" type="hinge" axis="1 0 0" pos="0 0 0" range="-90 90"/>
              <joint name="RightToe_y" type="hinge" axis="0 1 0" pos="0 0 0" range="-90 90"/>
              <joint name="RightToe_z" type="hinge" axis="0 0 1" pos="0 0 0" range="-90 90"/>
            </body>
          </body>
        </body>
      </body>

      <body name="Tail" pos="-0.000 0.130 -0.014">
        <geom type="capsule" fromto="0 0 0 -0.000 0.160 0.000" size="0.05" />
        <joint name="Tail_x" type="hinge" axis="1 0 0" pos="0 0 0" range="-90 90"/>
        <joint name="Tail_y" type="hinge" axis="0 1 0" pos="0 0 0" range="-90 90"/>
        <joint name="Tail_z" type="hinge" axis="0 0 1" pos="0 0 0" range="-90 90"/>

        <body name="Tail1" pos="-0.000 0.229 0.000">
          <geom type="capsule" fromto="0 0 0 -0.000 0.160 0.000" size="0.05" />
          <joint name="Tail1_x" type="hinge" axis="1 0 0" pos="0 0 0" range="-90 90"/>
          <joint name="Tail1_y" type="hinge" axis="0 1 0" pos="0 0 0" range="-90 90"/>
          <joint name="Tail1_z" type="hinge" axis="0 0 1" pos="0 0 0" range="-90 90"/>
        </body>
      </body>
    </body>
  </worldbody>

  <actuator>
    <motor name="Spine_x" joint="Spine_x"  />
    <motor name="Spine_y" joint="Spine_y"  />
    <motor name="Spine_z" joint="Spine_z"  />
    <motor name="Spine1_x" joint="Spine1_x"  />
    <motor name="Spine1_y" joint="Spine1_y"  />
    <motor name="Spine1_z" joint="Spine1_z"  />
    <motor name="Neck_x" joint="Neck_x"  />
    <motor name="Neck_y" joint="Neck_y"  />
    <motor name="Neck_z" joint="Neck_z"  />
    <motor name="Head_x" joint="Head_x"  />
    <motor name="Head_y" joint="Head_y"  />
    <motor name="Head_z" joint="Head_z"  />
    <motor name="LeftShoulder_x" joint="LeftShoulder_x"  />
    <motor name="LeftShoulder_y" joint="LeftShoulder_y"  />
    <motor name="LeftShoulder_z" joint="LeftShoulder_z"  />
    <motor name="LeftArm_x" joint="LeftArm_x"  />
    <motor name="LeftArm_y" joint="LeftArm_y"  />
    <motor name="LeftArm_z" joint="LeftArm_z"  />
    <motor name="LeftForeArm_x" joint="LeftForeArm_x"  />
    <motor name="LeftForeArm_y" joint="LeftForeArm_y"  />
    <motor name="LeftForeArm_z" joint="LeftForeArm_z"  />
    <motor name="LeftHand_x" joint="LeftHand_x"  />
    <motor name="LeftHand_y" joint="LeftHand_y"  />
    <motor name="LeftHand_z" joint="LeftHand_z"  />
    <motor name="LeftFinger_x" joint="LeftFinger_x"  />
    <motor name="LeftFinger_y" joint="LeftFinger_y"  />
    <motor name="LeftFinger_z" joint="LeftFinger_z"  />
    <motor name="RightShoulder_x" joint="RightShoulder_x"  />
    <motor name="RightShoulder_y" joint="RightShoulder_y"  />
    <motor name="RightShoulder_z" joint="RightShoulder_z"  />
    <motor name="RightArm_x" joint="RightArm_x"  />
    <motor name="RightArm_y" joint="RightArm_y"  />
    <motor name="RightArm_z" joint="RightArm_z"  />
    <motor name="RightForeArm_x" joint="RightForeArm_x"  />
    <motor name="RightForeArm_y" joint="RightForeArm_y"  />
    <motor name="RightForeArm_z" joint="RightForeArm_z"  />
    <motor name="RightHand_x" joint="RightHand_x"  />
    <motor name="RightHand_y" joint="RightHand_y"  />
    <motor name="RightHand_z" joint="RightHand_z"  />
    <motor name="RightFinger_x" joint="RightFinger_x"  />
    <motor name="RightFinger_y" joint="RightFinger_y"  />
    <motor name="RightFinger_z" joint="RightFinger_z"  />
    <motor name="LeftUpLeg_x" joint="LeftUpLeg_x"  />
    <motor name="LeftUpLeg_y" joint="LeftUpLeg_y"  />
    <motor name="LeftUpLeg_z" joint="LeftUpLeg_z"  />
    <motor name="LeftLeg_x" joint="LeftLeg_x"  />
    <motor name="LeftLeg_y" joint="LeftLeg_y"  />
    <motor name="LeftLeg_z" joint="LeftLeg_z"  />
    <motor name="LeftFoot_x" joint="LeftFoot_x"  />
    <motor name="LeftFoot_y" joint="LeftFoot_y"  />
    <motor name="LeftFoot_z" joint="LeftFoot_z"  />
    <motor name="LeftToe_x" joint="LeftToe_x"  />
    <motor name="LeftToe_y" joint="LeftToe_y"  />
    <motor name="LeftToe_z" joint="LeftToe_z"  />
    <motor name="RightUpLeg_x" joint="RightUpLeg_x"  />
    <motor name="RightUpLeg_y" joint="RightUpLeg_y"  />
    <motor name="RightUpLeg_z" joint="RightUpLeg_z"  />
    <motor name="RightLeg_x" joint="RightLeg_x"  />
    <motor name="RightLeg_y" joint="RightLeg_y"  />
    <motor name="RightLeg_z" joint="RightLeg_z"  />
    <motor name="RightFoot_x" joint="RightFoot_x"  />
    <motor name="RightFoot_y" joint="RightFoot_y"  />
    <motor name="RightFoot_z" joint="RightFoot_z"  />
    <motor name="RightToe_x" joint="RightToe_x"  />
    <motor name="RightToe_y" joint="RightToe_y"  />
    <motor name="RightToe_z" joint="RightToe_z"  />
    <motor name="Tail_x" joint="Tail_x"  />
    <motor name="Tail_y" joint="Tail_y"  />
    <motor name="Tail_z" joint="Tail_z"  />
    <motor name="Tail1_x" joint="Tail1_x"  />
    <motor name="Tail1_y" joint="Tail1_y"  />
    <motor name="Tail1_z" joint="Tail1_z"  />
  </actuator>
</mujoco>
