<mujoco model="dog">
  <statistic extent="2" center="0 0 1"/>

  <option timestep="0.00555"/>

  <default>
    <motor ctrlrange="-1 1" ctrllimited="true"/>
    <default class="body">
      <geom type="capsule" condim="1" friction="1.0 0.05 0.05" solimp=".9 .99 .003" solref=".015 1"/>
      <joint type="hinge" damping="0.1" stiffness="5" armature=".007" limited="true" solimplimit="0 .99 .01"/>
      <site size=".04" group="3"/>
      <default class="force-torque">
        <site type="box" size=".01 .01 .02" rgba="1 0 0 1" />
      </default>
      <default class="touch">
        <site type="capsule" rgba="0 0 1 .3"/>
      </default>
    </default>
  </default>

  <worldbody>
    <geom name="floor" type="plane" conaffinity="1" size="100 100 .2" />
    <body name="pelvis" pos="0 0 1" childclass="body">
      <freejoint name="root"/>
      <site name="root" class="force-torque"/>
      <geom name="pelvis" type="sphere" pos="0 0 -0.02" size=".06" mass="3"/>
      <site name="pelvis" class="touch" type="sphere" pos="0 0 -0.02" size="0.061"/>

      <body name="waist" pos="0 0 0">
        <joint name="spine0_x" pos="0 0 0" axis="1 0 0" range="-60 60" stiffness="1000" damping="100" armature=".02"/>
        <joint name="spine0_y" pos="0 0 0" axis="0 1 0" range="-60 60" stiffness="1000" damping="100" armature=".02"/>
        <joint name="spine0_z" pos="0 0 0" axis="0 0 1" range="-30 30" stiffness="1000" damping="100" armature=".02"/>
        <geom name="waist" type="sphere" pos="0.17 0 -0.025" size="0.1" mass="5"/>
        <!-- <geom name="joint_spine0" type="sphere" pos="0.075 0 -0.02" size="0.05" mass="2"/> -->
        <site name="waist" class="touch" type="sphere" pos="0.17 0 -0.025" size="0.11"/>
        <!-- <site name="joint_spine0" class="touch" type="sphere" pos="0.075 0 -0.02" size="0.051"/> -->
        
        <body name="torso" pos="0.237500 0 0">
          <light name="top" pos="0 0 2" mode="trackcom"/>
          <camera name="back" pos="-3 0 1" xyaxes="0 -1 0 1 0 2" mode="trackcom"/>
          <camera name="side" pos="0 -3 1" xyaxes="1 0 0 0 1 2" mode="trackcom"/>
          <joint name="spine1_x" pos="0 0 0" axis="1 0 0" range="-60 60" stiffness="1000" damping="100" armature=".02"/>
          <joint name="spine1_y" pos="0 0 0" axis="0 1 0" range="-60 90" stiffness="1000" damping="100" armature=".02"/>
          <joint name="spine1_z" pos="0 0 0" axis="0 0 1" range="-50 50" stiffness="1000" damping="100" armature=".02"/>
          <geom name="torso" type="sphere" pos="0.16 0 -0.04" size="0.12" mass="6"/>
          <!-- <geom name="joint_spine1" type="sphere" pos="0.035 0 -0.02" size="0.0725" mass="2.5"/> -->
          <site name="spine1" class="touch" type="sphere" pos="0.17 0 -0.04" size="0.121"/>
          <!-- <site name="joint_spine1" class="touch" type="sphere" pos="0.035 0 -0.02" size="0.0735"/> -->
          
          <body name="neck" pos="0.28135 0 0">
            <joint name="neck_x" pos="0 0 0" axis="1 0 0" range="-60 60" stiffness="100" damping="10" armature=".01"/>
            <joint name="neck_y" pos="0 0 0" axis="0 1 0" range="-90 90" stiffness="100" damping="10" armature=".01"/>
            <joint name="neck_z" pos="0 0 0" axis="0 0 1" range="-50 50" stiffness="100" damping="10" armature=".01"/>
            <geom name="neck" type="capsule" pos="0.075 0 0" euler="0 -90 0" size="0.035 0.04" mass="1"/>
            <site name="neck" class="touch" type="sphere" pos="0.12 0 0" size="0.111"/>
            
            <body name="head" pos="0.175 0 0">
              <joint name="head_x" pos="0 0 0" axis="1 0 0" range="-60 60" stiffness="100" damping="10" armature=".01"/>
              <joint name="head_y" pos="0 0 0" axis="0 1 0" range="-60 60" stiffness="100" damping="10" armature=".01"/>
              <joint name="head_z" pos="0 0 0" axis="0 0 1" range="-50 50" stiffness="100" damping="10" armature=".01"/>
              <geom name="head" type="box" pos="0.08 0 -0.04" size="0.06 0.05 0.095" mass="1.5"/>
              <site name="head" class="touch" type="box" pos="0.08 0 -0.04" size="0.061 0.051 0.096"/>
              <camera name="egocentric" pos=".103 0 0" euler="0 0 -90"/>
            </body>
          </body>

          <body name="left_shoulder" pos="0.304074 -0.106071 -0.109983">
            <joint name="left_shoulder_x" pos="0 0 0" axis="1 0 0" range="-60 60" stiffness="500" damping="50" armature=".02"/>
            <joint name="left_shoulder_y" pos="0 0 0" axis="0 1 0" range="-60 90" stiffness="500" damping="50" armature=".02"/>
            <joint name="left_shoulder_z" pos="0 0 0" axis="0 0 1" range="-50 50" stiffness="500" damping="50" armature=".02"/>
            <geom name="left_shoulder" type="capsule" pos="0 0 -0.05" size="0.04 0.06" mass="1.5"/>
            <site name="left_shoulder" class="touch" type="capsule" pos="0 0 -0.05" size="0.041 0.061"/>

            <body name="left_forearm" pos="0 0 -0.19">
              <joint name="left_forearm" pos="0 0 0" axis="0 1 0" range="-160 0" stiffness="400" damping="40" armature=".02"/>
              <geom name="left_forearm" type="capsule" pos="0 0 -0.08" size="0.03 0.105" mass="1"/>
              <site name="left_forearm" class="touch" type="capsule" pos="0 0 -0.08" size="0.031 0.106"/>

              <body name="left_hand" pos="0 0 -0.222500">
                <joint name="left_hand_x" pos="0 0 0" axis="1 0 0" range="-60 60" stiffness="300" damping="30" armature=".01"/>
                <joint name="left_hand_y" pos="0 0 0" axis="0 1 0" range="-60 60" stiffness="300" damping="30" armature=".01"/>
                <joint name="left_hand_z" pos="0 0 0" axis="0 0 1" range="-60 60" stiffness="300" damping="30" armature=".01"/>
                <geom name="left_hand" type="box" pos="0 0 -0.04" size="0.02 0.025 0.04" mass="0.5"/>
                <site name="left_hand" class="touch" type="box" pos="0 0 -0.04" size="0.021 0.026 0.041"/>

                <body name="left_finger" pos="0 0 -0.09">
                  <joint name="left_finger_x" pos="0 0 0" axis="1 0 0" range="-60 60" stiffness="200" damping="20" armature=".01"/>
                  <joint name="left_finger_y" pos="0 0 0" axis="0 1 0" range="-60 60" stiffness="200" damping="20" armature=".01"/>
                  <joint name="left_finger_z" pos="0 0 0" axis="0 0 1" range="-60 60" stiffness="200" damping="20" armature=".01"/>
                  <geom name="left_finger" type="box" pos="0.012 0 -0.02" size="0.04 0.025 0.02" mass="0.5"/>
                  <site name="left_finger" class="touch" type="box" pos="0.012 0 -0.02" size="0.041 0.026 0.021"/>
                </body>
              </body>
            </body>
          </body>

          <body name="right_shoulder" pos="0.304074 0.106071 -0.109983">
            <joint name="right_shoulder_x" pos="0 0 0" axis="1 0 0" range="-60 60" stiffness="600" damping="60" armature=".02"/>
            <joint name="right_shoulder_y" pos="0 0 0" axis="0 1 0" range="-60 90" stiffness="600" damping="60" armature=".02"/>
            <joint name="right_shoulder_z" pos="0 0 0" axis="0 0 1" range="-50 50" stiffness="600" damping="60" armature=".02"/>
            <geom name="right_shoulder" type="capsule" pos="0 0 -0.05" size="0.04 0.06" mass="1.5"/>
            <site name="right_shoulder" class="touch" type="capsule" pos="0 0 -0.05" size="0.041 0.061"/>

            <body name="right_forearm" pos="0 0 -0.19">
              <joint name="right_forearm" pos="0 0 0" axis="0 1 0" range="-180 0" stiffness="400" damping="40" armature=".02"/>
              <geom name="right_forearm" type="capsule" pos="0 0 -0.08" size="0.03 0.105" mass="1"/>
              <site name="right_forearm" class="touch" type="capsule" pos="0 0 -0.08" size="0.031 0.106"/>

              <body name="right_hand" pos="0 0 -0.222500">
                <joint name="right_hand_x" pos="0 0 0" axis="1 0 0" range="-60 60" stiffness="300" damping="30" armature=".02"/>
                <joint name="right_hand_y" pos="0 0 0" axis="0 1 0" range="-60 60" stiffness="300" damping="30" armature=".02"/>
                <joint name="right_hand_z" pos="0 0 0" axis="0 0 1" range="-60 60" stiffness="300" damping="30" armature=".02"/>
                <geom name="right_hand" type="box" pos="0 0 -0.04" size="0.02 0.025 0.04" mass="0.5"/>
                <site name="right_hand" class="touch" type="box" pos="0 0 -0.04" size="0.021 0.026 0.041"/>

                <body name="right_finger" pos="0 0 -0.09">
                  <joint name="right_finger_x" pos="0 0 0" axis="1 0 0" range="-60 60" stiffness="200" damping="20" armature=".01"/>
                  <joint name="right_finger_y" pos="0 0 0" axis="0 1 0" range="-60 60" stiffness="200" damping="20" armature=".01"/>
                  <joint name="right_finger_z" pos="0 0 0" axis="0 0 1" range="-60 60" stiffness="200" damping="20" armature=".01"/>
                  <geom name="right_finger" type="box" pos="0.012 0 -0.02" size="0.04 0.025 0.02" mass="0.5"/>
                  <site name="right_finger" class="touch" type="box" pos="0.012 0 -0.02" size="0.041 0.026 0.021"/>
                </body>
              </body>
            </body>
          </body>
        </body>
      </body>

      <body name="left_upper_leg" pos="-0.074803 -0.109860 -0.095825">
        <joint name="left_upper_leg_x" pos="0 0 0" axis="1 0 0" range="-120 60" stiffness="700" damping="70" armature=".02"/>
        <joint name="left_upper_leg_y" pos="0 0 0" axis="0 1 0" range="-90 90" stiffness="700" damping="70" armature=".02"/>
        <joint name="left_upper_leg_z" pos="0 0 0" axis="0 0 1" range="-50 50" stiffness="700" damping="70" armature=".02"/>
        <geom name="left_upper_leg" type="capsule" pos="0 0 -0.055" size="0.045 0.1" mass="1.5"/>
        <site name="left_upper_leg" class="touch" type="capsule" pos="0 0 -0.055" size="0.046 0.101"/>

        <body name="left_leg" pos="0 0 -0.2">
          <joint name="left_leg" pos="0 0 0" axis="0 1 0" range="-30 180" stiffness="500" damping="50" armature=".02"/>
          <geom name="left_leg" type="capsule" pos="0 0 -0.1" size="0.03 0.055" mass="1"/>
          <site name="left_leg" class="touch" type="capsule" pos="0 0 -0.1" size="0.031 0.056"/>

          <body name="left_foot" pos="0 0 -0.225">
            <joint name="left_foot_x" pos="0 0 0" axis="1 0 0" range="-60 60" stiffness="400" damping="40" armature=".02"/>
            <joint name="left_foot_y" pos="0 0 0" axis="0 1 0" range="-90 60" stiffness="400" damping="40" armature=".02"/>
            <joint name="left_foot_z" pos="0 0 0" axis="0 0 1" range="-60 60" stiffness="400" damping="40" armature=".02"/>
            <geom name="left_foot" type="box" pos="0 0 -0.04" size="0.025 0.025 0.07" mass="0.5"/>
            <site name="left_foot" class="touch" type="box" pos="0 0 -0.03" size="0.026 0.026 0.101"/>

            <body name="left_toe" pos="0 0 -0.135">
              <joint name="left_toe_x" pos="0 0 0" axis="1 0 0" range="-60 60" stiffness="200" damping="20" armature=".01"/>
              <joint name="left_toe_y" pos="0 0 0" axis="0 1 0" range="-60 60" stiffness="200" damping="20" armature=".01"/>
              <joint name="left_toe_z" pos="0 0 0" axis="0 0 1" range="-60 60" stiffness="200" damping="20" armature=".01"/>
              <geom name="left_toe" type="box" pos="0.015 0 -0.02" size="0.045 0.025 0.02" mass="0.5"/>
              <site name="left_toe" class="touch" type="box" pos="0.015 0 -0.02" size="0.046 0.026 0.021"/>
            </body>
          </body>
        </body>
      </body>

      <body name="right_upper_leg" pos="-0.074803 0.109860 -0.095825">
        <joint name="right_upper_leg_x" pos="0 0 0" axis="1 0 0" range="-120 60" stiffness="700" damping="70" armature=".02"/>
        <joint name="right_upper_leg_y" pos="0 0 0" axis="0 1 0" range="-90 90" stiffness="700" damping="70" armature=".02"/>
        <joint name="right_upper_leg_z" pos="0 0 0" axis="0 0 1" range="-50 50" stiffness="700" damping="70" armature=".02"/>
        <geom name="right_upper_leg" type="capsule" pos="0 0 -0.055" size="0.045 0.1" mass="1.5"/>
        <site name="right_upper_leg" class="touch" type="capsule" pos="0 0 -0.055" size="0.046 0.101"/>

        <body name="right_leg" pos="0 0 -0.2">
          <joint name="right_leg" pos="0 0 0" axis="0 1 0" range="-30 180" stiffness="500" damping="50" armature=".02"/>
          <geom name="right_leg" type="capsule" pos="0 0 -0.1" size="0.03 0.055" mass="1"/>
          <site name="right_leg" class="touch" type="capsule" pos="0 0 -0.1" size="0.031 0.056"/>

          <body name="right_foot" pos="0 0 -0.225">
            <joint name="right_foot_x" pos="0 0 0" axis="1 0 0" range="-60 60" stiffness="400" damping="40" armature=".02"/>
            <joint name="right_foot_y" pos="0 0 0" axis="0 1 0" range="-90 60" stiffness="400" damping="40" armature=".02"/>
            <joint name="right_foot_z" pos="0 0 0" axis="0 0 1" range="-60 60" stiffness="400" damping="40" armature=".02"/>
            <geom name="right_foot" type="box" pos="0 0 -0.04" size="0.025 0.025 0.07" mass="0.5"/>
            <site name="right_foot" class="touch" type="box" pos="0 0 -0.03" size="0.026 0.026 0.101"/>

            <body name="right_toe" pos="0 0 -0.135">
              <joint name="right_toe_x" pos="0 0 0" axis="1 0 0" range="-60 60" stiffness="200" damping="20" armature=".01"/>
              <joint name="right_toe_y" pos="0 0 0" axis="0 1 0" range="-60 60" stiffness="200" damping="20" armature=".01"/>
              <joint name="right_toe_z" pos="0 0 0" axis="0 0 1" range="-60 60" stiffness="200" damping="20" armature=".01"/>
              <geom name="right_toe" type="box" pos="0.015 0 -0.02" size="0.045 0.025 0.02" mass="0.5"/>
              <site name="right_toe" class="touch" type="box" pos="0.015 0 -0.02" size="0.046 0.026 0.021"/>
            </body>
          </body>
        </body>
      </body>

      <body name="tail0" pos="-0.086 0 0">
        <joint name="tail0_x" pos="0 0 0" axis="1 0 0" range="-60 60" stiffness="300" damping="30" armature=".01"/>
        <joint name="tail0_y" pos="0 0 0" axis="0 1 0" range="-90 90" stiffness="300" damping="30" armature=".01"/>
        <joint name="tail0_z" pos="0 0 0" axis="0 0 1" range="-50 50" stiffness="300" damping="30" armature=".01"/>
        <geom name="tail0" type="capsule" pos="-0.1 0 0" euler="0 90 0" size="0.025 0.07" mass="0.5"/>
        <site name="tail0" class="touch" type="capsule" pos="-0.1 0 0" size="0.026 0.071"/>

        <body name="tail1" pos="-0.2 0 0">
          <joint name="tail1_x" pos="0 0 0" axis="1 0 0" range="-60 60" stiffness="200" damping="20" armature=".01"/>
          <joint name="tail1_y" pos="0 0 0" axis="0 1 0" range="-60 90" stiffness="200" damping="20" armature=".01"/>
          <joint name="tail1_z" pos="0 0 0" axis="0 0 1" range="-50 50" stiffness="200" damping="20" armature=".01"/>
          <geom name="tail1" type="capsule" pos="-0.11 0 0" euler="0 90 0" size="0.02 0.085" mass="0.25"/>
          <site name="tail1" class="touch" type="capsule" pos="-0.11 0 0" size="0.021 0.086"/>
        </body>
      </body>
    </body>
  </worldbody>

  <actuator>
    <motor name="spine0_x"          gear="200" joint="spine0_x"/>
    <motor name="spine0_y"          gear="200" joint="spine0_y"/>
    <motor name="spine0_z"          gear="200" joint="spine0_z"/>
    <motor name="spine1_x"          gear="200" joint="spine1_x"/>
    <motor name="spine1_y"          gear="200" joint="spine1_y"/>
    <motor name="spine1_z"          gear="200" joint="spine1_z"/>
    <motor name="neck_x"            gear="50" joint="neck_x"/>
    <motor name="neck_y"            gear="50" joint="neck_y"/>
    <motor name="neck_z"            gear="50" joint="neck_z"/>
    <motor name="head_x"            gear="50"  joint="head_x"/>
    <motor name="head_y"            gear="50"  joint="head_y"/>
    <motor name="head_z"            gear="50"  joint="head_z"/>
    <motor name="left_shoulder_x"   gear="100" joint="left_shoulder_x"/>
    <motor name="left_shoulder_y"   gear="100" joint="left_shoulder_y"/>
    <motor name="left_shoulder_z"   gear="100" joint="left_shoulder_z"/>
    <motor name="left_forearm"      gear="70"  joint="left_forearm"/>
    <motor name="left_hand_x"       gear="50"  joint="left_hand_x"/>
    <motor name="left_hand_y"       gear="50"  joint="left_hand_y"/>
    <motor name="left_hand_z"       gear="50"  joint="left_hand_z"/>
    <motor name="left_finger_x"     gear="50"  joint="left_finger_x"/>
    <motor name="left_finger_y"     gear="50"  joint="left_finger_y"/>
    <motor name="left_finger_z"     gear="50"  joint="left_finger_z"/>
    <motor name="right_shoulder_x"  gear="100" joint="right_shoulder_x"/>
    <motor name="right_shoulder_y"  gear="100" joint="right_shoulder_y"/>
    <motor name="right_shoulder_z"  gear="100" joint="right_shoulder_z"/>
    <motor name="right_forearm"     gear="70"  joint="right_forearm"/>
    <motor name="right_hand_x"      gear="50"  joint="right_hand_x"/>
    <motor name="right_hand_y"      gear="50"  joint="right_hand_y"/>
    <motor name="right_hand_z"      gear="50"  joint="right_hand_z"/>
    <motor name="right_finger_x"    gear="50"  joint="right_finger_x"/>
    <motor name="right_finger_y"    gear="50"  joint="right_finger_y"/>
    <motor name="right_finger_z"    gear="50"  joint="right_finger_z"/>
    <motor name="left_upper_leg_x"  gear="200" joint="left_upper_leg_x"/>
    <motor name="left_upper_leg_y"  gear="200" joint="left_upper_leg_y"/>
    <motor name="left_upper_leg_z"  gear="200" joint="left_upper_leg_z"/>
    <motor name="left_leg"          gear="150"  joint="left_leg"/>
    <motor name="left_foot_x"       gear="100"  joint="left_foot_x"/>
    <motor name="left_foot_y"       gear="100"  joint="left_foot_y"/>
    <motor name="left_foot_z"       gear="100"  joint="left_foot_z"/>
    <motor name="left_toe_x"        gear="70"  joint="left_toe_x"/>
    <motor name="left_toe_y"        gear="70"  joint="left_toe_y"/>
    <motor name="left_toe_z"        gear="70"  joint="left_toe_z"/>
    <motor name="right_upper_leg_x" gear="200" joint="right_upper_leg_x"/>
    <motor name="right_upper_leg_y" gear="200" joint="right_upper_leg_y"/>
    <motor name="right_upper_leg_z" gear="200" joint="right_upper_leg_z"/>
    <motor name="right_leg"         gear="150"  joint="right_leg"/>
    <motor name="right_foot_x"      gear="100"  joint="right_foot_x"/>
    <motor name="right_foot_y"      gear="100"  joint="right_foot_y"/>
    <motor name="right_foot_z"      gear="100"  joint="right_foot_z"/>
    <motor name="right_toe_x"       gear="70"  joint="right_toe_x"/>
    <motor name="right_toe_y"       gear="70"  joint="right_toe_y"/>
    <motor name="right_toe_z"       gear="70"  joint="right_toe_z"/>
    <motor name="tail0_x"           gear="70"  joint="tail0_x"/>
    <motor name="tail0_y"           gear="70"  joint="tail0_y"/>
    <motor name="tail0_z"           gear="70"  joint="tail0_z"/>
    <motor name="tail1_x"           gear="70"  joint="tail1_x"/>
    <motor name="tail1_y"           gear="70"  joint="tail1_y"/>
    <motor name="tail1_z"           gear="70"  joint="tail1_z"/>
  </actuator>

  <sensor>
    <subtreelinvel name="pelvis_subtreelinvel" body="pelvis"/>
    <accelerometer name="root_accel"    site="root"/>
    <velocimeter name="root_vel"        site="root"/>
    <gyro name="root_gyro"              site="root"/>

    <touch name="pelvis_touch"          site="pelvis"/>
    <touch name="waist_touch"           site="waist"/>
    <!-- <touch name="joint_spine0_touch"    site="joint_spine0"/> -->
    <touch name="spine1_touch"          site="spine1"/>
    <!-- <touch name="joint_spine1_touch"    site="joint_spine1"/> -->
    <touch name="neck_touch"            site="neck"/>
    <touch name="head_touch"            site="head"/>
    <touch name="left_shoulder_touch"   site="left_shoulder"/>
    <touch name="left_forearm_touch"    site="left_forearm"/>
    <touch name="left_hand_touch"       site="left_hand"/>
    <touch name="left_finger_touch"     site="left_finger"/>
    <touch name="right_shoulder_touch"  site="right_shoulder"/>
    <touch name="right_forearm_touch"   site="right_forearm"/>
    <touch name="right_hand_touch"      site="right_hand"/>
    <touch name="right_finger_touch"    site="right_finger"/>
    <touch name="left_upper_leg_touch"  site="left_upper_leg"/>
    <touch name="left_leg_touch"        site="left_leg"/>
    <touch name="left_foot_touch"       site="left_foot"/>
    <touch name="left_toe_touch"        site="left_toe"/>
    <touch name="right_upper_leg_touch" site="right_upper_leg"/>
    <touch name="right_leg_touch"       site="right_leg"/>
    <touch name="right_foot_touch"      site="right_foot"/>
    <touch name="right_toe_touch"       site="right_toe"/>
    <touch name="tail0_touch"           site="tail0"/>
    <touch name="tail1_touch"           site="tail1"/>
  </sensor>
</mujoco>